<?xml version="1.0" ?>
<!-- =================================================================================== -->
<!-- |    This document was autogenerated by xacro from marv.xacro                     | -->
<!-- |    EDITING THIS FILE BY HAND IS NOT RECOMMENDED                                 | -->
<!-- =================================================================================== -->
<robot name="marv">
  <!-- Offset to prevent touching -->
  <!-- Link 1 -->
  <link name="link1">
    <visual>
      <geometry>
        <box size="0.1 0.1 1.0"/>
      </geometry>
      <origin xyz="0 0 0.5"/>
      <material name="blue">
        <color rgba="0 0 1 1"/>
      </material>
    </visual>
    <collision>
      <geometry>
        <box size="0.1 0.1 1.0"/>
      </geometry>
      <origin xyz="0 0 0.5"/>
    </collision>
    <inertial>
      <mass value="1.0"/>
      <origin xyz="0 0 0.5"/>
      <inertia ixx="0.01" ixy="0" ixz="0" iyy="0.01" iyz="0" izz="0.01"/>
    </inertial>
  </link>
  <!-- Joint -->
  <joint name="joint1" type="revolute">
    <parent link="link1"/>
    <child link="link2"/>
    <origin xyz="0 0 1.05"/>
    <!-- Offset added -->
    <axis xyz="1 0 0"/>
    <limit effort="10.0" lower="-3.14" upper="3.14" velocity="1.0"/>
    <dynamics damping="0.5" friction="0.1"/>
  </joint>
  <!-- Link 2 -->
  <link name="link2">
    <visual>
      <geometry>
        <box size="0.1 0.1 1.0"/>
      </geometry>
      <origin xyz="0 0 0.5"/>
      <material name="red">
        <color rgba="1 0 0 1"/>
      </material>
    </visual>
    <collision>
      <geometry>
        <box size="0.1 0.1 1.0"/>
      </geometry>
      <origin xyz="0 0 0.5"/>
    </collision>
    <inertial>
      <mass value="1.0"/>
      <origin xyz="0 0 0.5"/>
      <inertia ixx="0.01" ixy="0" ixz="0" iyy="0.01" iyz="0" izz="0.01"/>
    </inertial>
  </link>
</robot>
